[2025-04-22T21:48:26.847+0000] {local_task_job_runner.py:123} INFO - ::group::Pre task execution logs
[2025-04-22T21:48:26.861+0000] {taskinstance.py:2612} INFO - Dependencies all met for dep_context=non-requeueable deps ti=<TaskInstance: law_enforcement_ELT_dbtcloud.trigger_dbt_job manual__2025-04-22T21:48:25.554594+00:00 [queued]>
[2025-04-22T21:48:26.883+0000] {taskinstance.py:2612} INFO - Dependencies all met for dep_context=requeueable deps ti=<TaskInstance: law_enforcement_ELT_dbtcloud.trigger_dbt_job manual__2025-04-22T21:48:25.554594+00:00 [queued]>
[2025-04-22T21:48:26.884+0000] {taskinstance.py:2865} INFO - Starting attempt 1 of 1
[2025-04-22T21:48:26.913+0000] {taskinstance.py:2888} INFO - Executing <Task(DbtCloudRunJobOperator): trigger_dbt_job> on 2025-04-22 21:48:25.554594+00:00
[2025-04-22T21:48:26.954+0000] {logging_mixin.py:190} WARNING - /home/***/.local/lib/python3.12/site-packages/***/task/task_runner/standard_task_runner.py:70 DeprecationWarning: This process (pid=508) is multi-threaded, use of fork() may lead to deadlocks in the child.
[2025-04-22T21:48:26.953+0000] {standard_task_runner.py:104} INFO - Running: ['***', 'tasks', 'run', 'law_enforcement_ELT_dbtcloud', 'trigger_dbt_job', 'manual__2025-04-22T21:48:25.554594+00:00', '--job-id', '563', '--raw', '--subdir', 'DAGS_FOLDER/__pycache__/Lab2_ELT.py', '--cfg-path', '/tmp/tmp3r31xfe_']
[2025-04-22T21:48:26.957+0000] {standard_task_runner.py:105} INFO - Job 563: Subtask trigger_dbt_job
[2025-04-22T21:48:26.957+0000] {standard_task_runner.py:72} INFO - Started process 509 to run task
[2025-04-22T21:48:27.077+0000] {task_command.py:467} INFO - Running <TaskInstance: law_enforcement_ELT_dbtcloud.trigger_dbt_job manual__2025-04-22T21:48:25.554594+00:00 [running]> on host 3fa5927efcb0
[2025-04-22T21:48:27.413+0000] {taskinstance.py:3131} INFO - Exporting env vars: AIRFLOW_CTX_DAG_OWNER='***' AIRFLOW_CTX_DAG_ID='law_enforcement_ELT_dbtcloud' AIRFLOW_CTX_TASK_ID='trigger_dbt_job' AIRFLOW_CTX_EXECUTION_DATE='2025-04-22T21:48:25.554594+00:00' AIRFLOW_CTX_TRY_NUMBER='1' AIRFLOW_CTX_DAG_RUN_ID='manual__2025-04-22T21:48:25.554594+00:00'
[2025-04-22T21:48:27.421+0000] {taskinstance.py:731} INFO - ::endgroup::
[2025-04-22T21:48:27.490+0000] {connection.py:277} WARNING - Connection schemes (type: dbt_cloud) shall not contain '_' according to RFC3986.
[2025-04-22T21:48:27.491+0000] {base.py:84} INFO - Retrieving connection 'dbt_cloud'
[2025-04-22T21:48:27.973+0000] {http.py:204} ERROR - HTTP error: Unauthorized
[2025-04-22T21:48:27.975+0000] {http.py:205} ERROR - {"status": {"code": 401, "is_success": false, "user_message": "Invalid token.", "developer_message": null}, "data": null}
[2025-04-22T21:48:28.011+0000] {taskinstance.py:3310} ERROR - Task failed with exception
Traceback (most recent call last):
  File "/home/airflow/.local/lib/python3.12/site-packages/airflow/providers/http/hooks/http.py", line 202, in check_response
    response.raise_for_status()
  File "/home/airflow/.local/lib/python3.12/site-packages/requests/models.py", line 1024, in raise_for_status
    raise HTTPError(http_error_msg, response=self)
requests.exceptions.HTTPError: 401 Client Error: Unauthorized for url: https://cloud.getdbt.com/api/v2/accounts/70471823454988/jobs/70471823455826/run/

During handling of the above exception, another exception occurred:

Traceback (most recent call last):
  File "/home/airflow/.local/lib/python3.12/site-packages/airflow/models/taskinstance.py", line 767, in _execute_task
    result = _execute_callable(context=context, **execute_callable_kwargs)
             ^^^^^^^^^^^^^^^^^^^^^^^^^^^^^^^^^^^^^^^^^^^^^^^^^^^^^^^^^^^^^
  File "/home/airflow/.local/lib/python3.12/site-packages/airflow/models/taskinstance.py", line 733, in _execute_callable
    return ExecutionCallableRunner(
           ^^^^^^^^^^^^^^^^^^^^^^^^
  File "/home/airflow/.local/lib/python3.12/site-packages/airflow/utils/operator_helpers.py", line 252, in run
    return self.func(*args, **kwargs)
           ^^^^^^^^^^^^^^^^^^^^^^^^^^
  File "/home/airflow/.local/lib/python3.12/site-packages/airflow/models/baseoperator.py", line 406, in wrapper
    return func(self, *args, **kwargs)
           ^^^^^^^^^^^^^^^^^^^^^^^^^^^
  File "/home/airflow/.local/lib/python3.12/site-packages/airflow/providers/dbt/cloud/operators/dbt.py", line 187, in execute
    trigger_job_response = self.hook.trigger_job_run(
                           ^^^^^^^^^^^^^^^^^^^^^^^^^^
  File "/home/airflow/.local/lib/python3.12/site-packages/airflow/providers/dbt/cloud/hooks/dbt.py", line 68, in wrapper
    return func(*bound_args.args, **bound_args.kwargs)
           ^^^^^^^^^^^^^^^^^^^^^^^^^^^^^^^^^^^^^^^^^^^
  File "/home/airflow/.local/lib/python3.12/site-packages/airflow/providers/dbt/cloud/hooks/dbt.py", line 603, in trigger_job_run
    return self._run_and_get_response(
           ^^^^^^^^^^^^^^^^^^^^^^^^^^^
  File "/home/airflow/.local/lib/python3.12/site-packages/airflow/providers/dbt/cloud/hooks/dbt.py", line 342, in _run_and_get_response
    return self.run(endpoint=full_endpoint, data=payload, extra_options=extra_options)
           ^^^^^^^^^^^^^^^^^^^^^^^^^^^^^^^^^^^^^^^^^^^^^^^^^^^^^^^^^^^^^^^^^^^^^^^^^^^
  File "/home/airflow/.local/lib/python3.12/site-packages/airflow/providers/http/hooks/http.py", line 191, in run
    return self.run_and_check(session, prepped_request, extra_options)
           ^^^^^^^^^^^^^^^^^^^^^^^^^^^^^^^^^^^^^^^^^^^^^^^^^^^^^^^^^^^
  File "/home/airflow/.local/lib/python3.12/site-packages/airflow/providers/http/hooks/http.py", line 244, in run_and_check
    self.check_response(response)
  File "/home/airflow/.local/lib/python3.12/site-packages/airflow/providers/http/hooks/http.py", line 206, in check_response
    raise AirflowException(str(response.status_code) + ":" + response.reason)
airflow.exceptions.AirflowException: 401:Unauthorized
[2025-04-22T21:48:28.026+0000] {taskinstance.py:1225} INFO - Marking task as FAILED. dag_id=law_enforcement_ELT_dbtcloud, task_id=trigger_dbt_job, run_id=manual__2025-04-22T21:48:25.554594+00:00, execution_date=20250422T214825, start_date=20250422T214826, end_date=20250422T214828
[2025-04-22T21:48:28.041+0000] {taskinstance.py:340} INFO - ::group::Post task execution logs
[2025-04-22T21:48:28.041+0000] {standard_task_runner.py:124} ERROR - Failed to execute job 563 for task trigger_dbt_job (401:Unauthorized; 509)
Traceback (most recent call last):
  File "/home/airflow/.local/lib/python3.12/site-packages/airflow/providers/http/hooks/http.py", line 202, in check_response
    response.raise_for_status()
  File "/home/airflow/.local/lib/python3.12/site-packages/requests/models.py", line 1024, in raise_for_status
    raise HTTPError(http_error_msg, response=self)
requests.exceptions.HTTPError: 401 Client Error: Unauthorized for url: https://cloud.getdbt.com/api/v2/accounts/70471823454988/jobs/70471823455826/run/

During handling of the above exception, another exception occurred:

Traceback (most recent call last):
  File "/home/airflow/.local/lib/python3.12/site-packages/airflow/task/task_runner/standard_task_runner.py", line 117, in _start_by_fork
    ret = args.func(args, dag=self.dag)
          ^^^^^^^^^^^^^^^^^^^^^^^^^^^^^
  File "/home/airflow/.local/lib/python3.12/site-packages/airflow/cli/cli_config.py", line 49, in command
    return func(*args, **kwargs)
           ^^^^^^^^^^^^^^^^^^^^^
  File "/home/airflow/.local/lib/python3.12/site-packages/airflow/utils/cli.py", line 115, in wrapper
    return f(*args, **kwargs)
           ^^^^^^^^^^^^^^^^^^
  File "/home/airflow/.local/lib/python3.12/site-packages/airflow/cli/commands/task_command.py", line 483, in task_run
    task_return_code = _run_task_by_selected_method(args, _dag, ti)
                       ^^^^^^^^^^^^^^^^^^^^^^^^^^^^^^^^^^^^^^^^^^^^
  File "/home/airflow/.local/lib/python3.12/site-packages/airflow/cli/commands/task_command.py", line 256, in _run_task_by_selected_method
    return _run_raw_task(args, ti)
           ^^^^^^^^^^^^^^^^^^^^^^^
  File "/home/airflow/.local/lib/python3.12/site-packages/airflow/cli/commands/task_command.py", line 341, in _run_raw_task
    return ti._run_raw_task(
           ^^^^^^^^^^^^^^^^^
  File "/home/airflow/.local/lib/python3.12/site-packages/airflow/utils/session.py", line 97, in wrapper
    return func(*args, session=session, **kwargs)
           ^^^^^^^^^^^^^^^^^^^^^^^^^^^^^^^^^^^^^^
  File "/home/airflow/.local/lib/python3.12/site-packages/airflow/models/taskinstance.py", line 3004, in _run_raw_task
    return _run_raw_task(
           ^^^^^^^^^^^^^^
  File "/home/airflow/.local/lib/python3.12/site-packages/airflow/models/taskinstance.py", line 273, in _run_raw_task
    TaskInstance._execute_task_with_callbacks(
  File "/home/airflow/.local/lib/python3.12/site-packages/airflow/models/taskinstance.py", line 3158, in _execute_task_with_callbacks
    result = self._execute_task(context, task_orig)
             ^^^^^^^^^^^^^^^^^^^^^^^^^^^^^^^^^^^^^^
  File "/home/airflow/.local/lib/python3.12/site-packages/airflow/models/taskinstance.py", line 3182, in _execute_task
    return _execute_task(self, context, task_orig)
           ^^^^^^^^^^^^^^^^^^^^^^^^^^^^^^^^^^^^^^^
  File "/home/airflow/.local/lib/python3.12/site-packages/airflow/models/taskinstance.py", line 767, in _execute_task
    result = _execute_callable(context=context, **execute_callable_kwargs)
             ^^^^^^^^^^^^^^^^^^^^^^^^^^^^^^^^^^^^^^^^^^^^^^^^^^^^^^^^^^^^^
  File "/home/airflow/.local/lib/python3.12/site-packages/airflow/models/taskinstance.py", line 733, in _execute_callable
    return ExecutionCallableRunner(
           ^^^^^^^^^^^^^^^^^^^^^^^^
  File "/home/airflow/.local/lib/python3.12/site-packages/airflow/utils/operator_helpers.py", line 252, in run
    return self.func(*args, **kwargs)
           ^^^^^^^^^^^^^^^^^^^^^^^^^^
  File "/home/airflow/.local/lib/python3.12/site-packages/airflow/models/baseoperator.py", line 406, in wrapper
    return func(self, *args, **kwargs)
           ^^^^^^^^^^^^^^^^^^^^^^^^^^^
  File "/home/airflow/.local/lib/python3.12/site-packages/airflow/providers/dbt/cloud/operators/dbt.py", line 187, in execute
    trigger_job_response = self.hook.trigger_job_run(
                           ^^^^^^^^^^^^^^^^^^^^^^^^^^
  File "/home/airflow/.local/lib/python3.12/site-packages/airflow/providers/dbt/cloud/hooks/dbt.py", line 68, in wrapper
    return func(*bound_args.args, **bound_args.kwargs)
           ^^^^^^^^^^^^^^^^^^^^^^^^^^^^^^^^^^^^^^^^^^^
  File "/home/airflow/.local/lib/python3.12/site-packages/airflow/providers/dbt/cloud/hooks/dbt.py", line 603, in trigger_job_run
    return self._run_and_get_response(
           ^^^^^^^^^^^^^^^^^^^^^^^^^^^
  File "/home/airflow/.local/lib/python3.12/site-packages/airflow/providers/dbt/cloud/hooks/dbt.py", line 342, in _run_and_get_response
    return self.run(endpoint=full_endpoint, data=payload, extra_options=extra_options)
           ^^^^^^^^^^^^^^^^^^^^^^^^^^^^^^^^^^^^^^^^^^^^^^^^^^^^^^^^^^^^^^^^^^^^^^^^^^^
  File "/home/airflow/.local/lib/python3.12/site-packages/airflow/providers/http/hooks/http.py", line 191, in run
    return self.run_and_check(session, prepped_request, extra_options)
           ^^^^^^^^^^^^^^^^^^^^^^^^^^^^^^^^^^^^^^^^^^^^^^^^^^^^^^^^^^^
  File "/home/airflow/.local/lib/python3.12/site-packages/airflow/providers/http/hooks/http.py", line 244, in run_and_check
    self.check_response(response)
  File "/home/airflow/.local/lib/python3.12/site-packages/airflow/providers/http/hooks/http.py", line 206, in check_response
    raise AirflowException(str(response.status_code) + ":" + response.reason)
airflow.exceptions.AirflowException: 401:Unauthorized
[2025-04-22T21:48:28.070+0000] {local_task_job_runner.py:266} INFO - Task exited with return code 1
[2025-04-22T21:48:28.114+0000] {taskinstance.py:3900} INFO - 0 downstream tasks scheduled from follow-on schedule check
[2025-04-22T21:48:28.116+0000] {local_task_job_runner.py:245} INFO - ::endgroup::
