[2025-03-15T01:31:22.327+0000] {processor.py:186} INFO - Started process (PID=244) to work on /opt/airflow/dags/train_predict.py
[2025-03-15T01:31:22.328+0000] {processor.py:914} INFO - Processing file /opt/airflow/dags/train_predict.py for tasks to queue
[2025-03-15T01:31:22.329+0000] {logging_mixin.py:190} INFO - [2025-03-15T01:31:22.329+0000] {dagbag.py:587} INFO - Filling up the DagBag from /opt/airflow/dags/train_predict.py
[2025-03-15T01:31:22.343+0000] {logging_mixin.py:190} INFO - [2025-03-15T01:31:22.343+0000] {base.py:84} INFO - Retrieving connection 'snowflake_conn'
[2025-03-15T01:31:22.344+0000] {logging_mixin.py:190} INFO - [2025-03-15T01:31:22.344+0000] {connection.py:413} INFO - Snowflake Connector for Python Version: 3.12.1, Python Version: 3.12.5, Platform: Linux-6.12.5-linuxkit-aarch64-with-glibc2.36
[2025-03-15T01:31:22.345+0000] {logging_mixin.py:190} INFO - [2025-03-15T01:31:22.345+0000] {connection.py:1196} INFO - Connecting to GLOBAL Snowflake domain
[2025-03-15T01:31:22.345+0000] {logging_mixin.py:190} INFO - [2025-03-15T01:31:22.345+0000] {connection.py:1277} INFO - This connection is in OCSP Fail Open Mode. TLS Certificates would be checked for validity and revocation status. Any other Certificate Revocation related exceptions or OCSP Responder failures would be disregarded in favor of connectivity.
[2025-03-15T01:31:22.668+0000] {logging_mixin.py:190} INFO - [2025-03-15T01:31:22.667+0000] {dagbag.py:386} ERROR - Failed to import: /opt/airflow/dags/train_predict.py
Traceback (most recent call last):
  File "/home/airflow/.local/lib/python3.12/site-packages/airflow/models/dagbag.py", line 382, in parse
    loader.exec_module(new_module)
  File "<frozen importlib._bootstrap_external>", line 995, in exec_module
  File "<frozen importlib._bootstrap>", line 488, in _call_with_frames_removed
  File "/opt/airflow/dags/train_predict.py", line 96, in <module>
    cur = return_snowflake_conn()
          ^^^^^^^^^^^^^^^^^^^^^^^
  File "/opt/airflow/dags/train_predict.py", line 18, in return_snowflake_conn
    conn = hook.get_conn()
           ^^^^^^^^^^^^^^^
  File "/home/airflow/.local/lib/python3.12/site-packages/airflow/providers/snowflake/hooks/snowflake.py", line 300, in get_conn
    conn = connector.connect(**conn_config)
           ^^^^^^^^^^^^^^^^^^^^^^^^^^^^^^^^
  File "/home/airflow/.local/lib/python3.12/site-packages/snowflake/connector/__init__.py", line 55, in Connect
    return SnowflakeConnection(**kwargs)
           ^^^^^^^^^^^^^^^^^^^^^^^^^^^^^
  File "/home/airflow/.local/lib/python3.12/site-packages/snowflake/connector/connection.py", line 456, in __init__
    self.connect(**kwargs)
  File "/home/airflow/.local/lib/python3.12/site-packages/snowflake/connector/connection.py", line 771, in connect
    self.__open_connection()
  File "/home/airflow/.local/lib/python3.12/site-packages/snowflake/connector/connection.py", line 1099, in __open_connection
    self.authenticate_with_retry(self.auth_class)
  File "/home/airflow/.local/lib/python3.12/site-packages/snowflake/connector/connection.py", line 1386, in authenticate_with_retry
    self._authenticate(auth_instance)
  File "/home/airflow/.local/lib/python3.12/site-packages/snowflake/connector/connection.py", line 1414, in _authenticate
    auth.authenticate(
  File "/home/airflow/.local/lib/python3.12/site-packages/snowflake/connector/auth/_auth.py", line 401, in authenticate
    Error.errorhandler_wrapper(
  File "/home/airflow/.local/lib/python3.12/site-packages/snowflake/connector/errors.py", line 284, in errorhandler_wrapper
    handed_over = Error.hand_to_other_handler(
                  ^^^^^^^^^^^^^^^^^^^^^^^^^^^^
  File "/home/airflow/.local/lib/python3.12/site-packages/snowflake/connector/errors.py", line 342, in hand_to_other_handler
    connection.errorhandler(connection, cursor, error_class, error_value)
  File "/home/airflow/.local/lib/python3.12/site-packages/snowflake/connector/errors.py", line 215, in default_errorhandler
    raise error_class(
snowflake.connector.errors.DatabaseError: 250001 (08001): None: Failed to connect to DB: EYRGUED-VJB46211.snowflakecomputing.com:443. Your user account has been temporarily locked. Try again later or contact your account administrator for assistance. For more information about this error, go to https://community.snowflake.com/s/error-your-user-login-has-been-locked.
[2025-03-15T01:31:22.671+0000] {processor.py:927} WARNING - No viable dags retrieved from /opt/airflow/dags/train_predict.py
[2025-03-15T01:31:22.677+0000] {processor.py:208} INFO - Processing /opt/airflow/dags/train_predict.py took 0.353 seconds
[2025-03-15T01:31:53.603+0000] {processor.py:186} INFO - Started process (PID=302) to work on /opt/airflow/dags/train_predict.py
[2025-03-15T01:31:53.606+0000] {processor.py:914} INFO - Processing file /opt/airflow/dags/train_predict.py for tasks to queue
[2025-03-15T01:31:53.608+0000] {logging_mixin.py:190} INFO - [2025-03-15T01:31:53.608+0000] {dagbag.py:587} INFO - Filling up the DagBag from /opt/airflow/dags/train_predict.py
[2025-03-15T01:31:53.619+0000] {logging_mixin.py:190} INFO - [2025-03-15T01:31:53.619+0000] {base.py:84} INFO - Retrieving connection 'snowflake_conn'
[2025-03-15T01:31:53.620+0000] {logging_mixin.py:190} INFO - [2025-03-15T01:31:53.620+0000] {connection.py:413} INFO - Snowflake Connector for Python Version: 3.12.1, Python Version: 3.12.5, Platform: Linux-6.12.5-linuxkit-aarch64-with-glibc2.36
[2025-03-15T01:31:53.621+0000] {logging_mixin.py:190} INFO - [2025-03-15T01:31:53.621+0000] {connection.py:1196} INFO - Connecting to GLOBAL Snowflake domain
[2025-03-15T01:31:53.622+0000] {logging_mixin.py:190} INFO - [2025-03-15T01:31:53.622+0000] {connection.py:1277} INFO - This connection is in OCSP Fail Open Mode. TLS Certificates would be checked for validity and revocation status. Any other Certificate Revocation related exceptions or OCSP Responder failures would be disregarded in favor of connectivity.
[2025-03-15T01:31:54.010+0000] {logging_mixin.py:190} INFO - [2025-03-15T01:31:54.009+0000] {dagbag.py:386} ERROR - Failed to import: /opt/airflow/dags/train_predict.py
Traceback (most recent call last):
  File "/home/airflow/.local/lib/python3.12/site-packages/airflow/models/dagbag.py", line 382, in parse
    loader.exec_module(new_module)
  File "<frozen importlib._bootstrap_external>", line 995, in exec_module
  File "<frozen importlib._bootstrap>", line 488, in _call_with_frames_removed
  File "/opt/airflow/dags/train_predict.py", line 96, in <module>
    cur = return_snowflake_conn()
          ^^^^^^^^^^^^^^^^^^^^^^^
  File "/opt/airflow/dags/train_predict.py", line 18, in return_snowflake_conn
    conn = hook.get_conn()
           ^^^^^^^^^^^^^^^
  File "/home/airflow/.local/lib/python3.12/site-packages/airflow/providers/snowflake/hooks/snowflake.py", line 300, in get_conn
    conn = connector.connect(**conn_config)
           ^^^^^^^^^^^^^^^^^^^^^^^^^^^^^^^^
  File "/home/airflow/.local/lib/python3.12/site-packages/snowflake/connector/__init__.py", line 55, in Connect
    return SnowflakeConnection(**kwargs)
           ^^^^^^^^^^^^^^^^^^^^^^^^^^^^^
  File "/home/airflow/.local/lib/python3.12/site-packages/snowflake/connector/connection.py", line 456, in __init__
    self.connect(**kwargs)
  File "/home/airflow/.local/lib/python3.12/site-packages/snowflake/connector/connection.py", line 771, in connect
    self.__open_connection()
  File "/home/airflow/.local/lib/python3.12/site-packages/snowflake/connector/connection.py", line 1099, in __open_connection
    self.authenticate_with_retry(self.auth_class)
  File "/home/airflow/.local/lib/python3.12/site-packages/snowflake/connector/connection.py", line 1386, in authenticate_with_retry
    self._authenticate(auth_instance)
  File "/home/airflow/.local/lib/python3.12/site-packages/snowflake/connector/connection.py", line 1414, in _authenticate
    auth.authenticate(
  File "/home/airflow/.local/lib/python3.12/site-packages/snowflake/connector/auth/_auth.py", line 401, in authenticate
    Error.errorhandler_wrapper(
  File "/home/airflow/.local/lib/python3.12/site-packages/snowflake/connector/errors.py", line 284, in errorhandler_wrapper
    handed_over = Error.hand_to_other_handler(
                  ^^^^^^^^^^^^^^^^^^^^^^^^^^^^
  File "/home/airflow/.local/lib/python3.12/site-packages/snowflake/connector/errors.py", line 342, in hand_to_other_handler
    connection.errorhandler(connection, cursor, error_class, error_value)
  File "/home/airflow/.local/lib/python3.12/site-packages/snowflake/connector/errors.py", line 215, in default_errorhandler
    raise error_class(
snowflake.connector.errors.DatabaseError: 250001 (08001): None: Failed to connect to DB: EYRGUED-VJB46211.snowflakecomputing.com:443. Your user account has been temporarily locked. Try again later or contact your account administrator for assistance. For more information about this error, go to https://community.snowflake.com/s/error-your-user-login-has-been-locked.
[2025-03-15T01:31:54.010+0000] {processor.py:927} WARNING - No viable dags retrieved from /opt/airflow/dags/train_predict.py
[2025-03-15T01:31:54.015+0000] {processor.py:208} INFO - Processing /opt/airflow/dags/train_predict.py took 0.414 seconds
[2025-03-15T01:32:24.105+0000] {processor.py:186} INFO - Started process (PID=348) to work on /opt/airflow/dags/train_predict.py
[2025-03-15T01:32:24.106+0000] {processor.py:914} INFO - Processing file /opt/airflow/dags/train_predict.py for tasks to queue
[2025-03-15T01:32:24.107+0000] {logging_mixin.py:190} INFO - [2025-03-15T01:32:24.106+0000] {dagbag.py:587} INFO - Filling up the DagBag from /opt/airflow/dags/train_predict.py
[2025-03-15T01:32:24.115+0000] {logging_mixin.py:190} INFO - [2025-03-15T01:32:24.115+0000] {base.py:84} INFO - Retrieving connection 'snowflake_conn'
[2025-03-15T01:32:24.115+0000] {logging_mixin.py:190} INFO - [2025-03-15T01:32:24.115+0000] {connection.py:413} INFO - Snowflake Connector for Python Version: 3.12.1, Python Version: 3.12.5, Platform: Linux-6.12.5-linuxkit-aarch64-with-glibc2.36
[2025-03-15T01:32:24.115+0000] {logging_mixin.py:190} INFO - [2025-03-15T01:32:24.115+0000] {connection.py:1196} INFO - Connecting to GLOBAL Snowflake domain
[2025-03-15T01:32:24.116+0000] {logging_mixin.py:190} INFO - [2025-03-15T01:32:24.115+0000] {connection.py:1277} INFO - This connection is in OCSP Fail Open Mode. TLS Certificates would be checked for validity and revocation status. Any other Certificate Revocation related exceptions or OCSP Responder failures would be disregarded in favor of connectivity.
[2025-03-15T01:32:24.284+0000] {logging_mixin.py:190} INFO - [2025-03-15T01:32:24.283+0000] {dagbag.py:386} ERROR - Failed to import: /opt/airflow/dags/train_predict.py
Traceback (most recent call last):
  File "/home/airflow/.local/lib/python3.12/site-packages/airflow/models/dagbag.py", line 382, in parse
    loader.exec_module(new_module)
  File "<frozen importlib._bootstrap_external>", line 995, in exec_module
  File "<frozen importlib._bootstrap>", line 488, in _call_with_frames_removed
  File "/opt/airflow/dags/train_predict.py", line 96, in <module>
    cur = return_snowflake_conn()
          ^^^^^^^^^^^^^^^^^^^^^^^
  File "/opt/airflow/dags/train_predict.py", line 18, in return_snowflake_conn
    conn = hook.get_conn()
           ^^^^^^^^^^^^^^^
  File "/home/airflow/.local/lib/python3.12/site-packages/airflow/providers/snowflake/hooks/snowflake.py", line 300, in get_conn
    conn = connector.connect(**conn_config)
           ^^^^^^^^^^^^^^^^^^^^^^^^^^^^^^^^
  File "/home/airflow/.local/lib/python3.12/site-packages/snowflake/connector/__init__.py", line 55, in Connect
    return SnowflakeConnection(**kwargs)
           ^^^^^^^^^^^^^^^^^^^^^^^^^^^^^
  File "/home/airflow/.local/lib/python3.12/site-packages/snowflake/connector/connection.py", line 456, in __init__
    self.connect(**kwargs)
  File "/home/airflow/.local/lib/python3.12/site-packages/snowflake/connector/connection.py", line 771, in connect
    self.__open_connection()
  File "/home/airflow/.local/lib/python3.12/site-packages/snowflake/connector/connection.py", line 1099, in __open_connection
    self.authenticate_with_retry(self.auth_class)
  File "/home/airflow/.local/lib/python3.12/site-packages/snowflake/connector/connection.py", line 1386, in authenticate_with_retry
    self._authenticate(auth_instance)
  File "/home/airflow/.local/lib/python3.12/site-packages/snowflake/connector/connection.py", line 1414, in _authenticate
    auth.authenticate(
  File "/home/airflow/.local/lib/python3.12/site-packages/snowflake/connector/auth/_auth.py", line 401, in authenticate
    Error.errorhandler_wrapper(
  File "/home/airflow/.local/lib/python3.12/site-packages/snowflake/connector/errors.py", line 284, in errorhandler_wrapper
    handed_over = Error.hand_to_other_handler(
                  ^^^^^^^^^^^^^^^^^^^^^^^^^^^^
  File "/home/airflow/.local/lib/python3.12/site-packages/snowflake/connector/errors.py", line 342, in hand_to_other_handler
    connection.errorhandler(connection, cursor, error_class, error_value)
  File "/home/airflow/.local/lib/python3.12/site-packages/snowflake/connector/errors.py", line 215, in default_errorhandler
    raise error_class(
snowflake.connector.errors.DatabaseError: 250001 (08001): None: Failed to connect to DB: EYRGUED-VJB46211.snowflakecomputing.com:443. Your user account has been temporarily locked. Try again later or contact your account administrator for assistance. For more information about this error, go to https://community.snowflake.com/s/error-your-user-login-has-been-locked.
[2025-03-15T01:32:24.284+0000] {processor.py:927} WARNING - No viable dags retrieved from /opt/airflow/dags/train_predict.py
[2025-03-15T01:32:24.288+0000] {processor.py:208} INFO - Processing /opt/airflow/dags/train_predict.py took 0.186 seconds
[2025-03-15T01:49:26.005+0000] {processor.py:186} INFO - Started process (PID=386) to work on /opt/airflow/dags/train_predict.py
[2025-03-15T01:49:26.007+0000] {processor.py:914} INFO - Processing file /opt/airflow/dags/train_predict.py for tasks to queue
[2025-03-15T01:49:26.009+0000] {logging_mixin.py:190} INFO - [2025-03-15T01:49:26.008+0000] {dagbag.py:587} INFO - Filling up the DagBag from /opt/airflow/dags/train_predict.py
[2025-03-15T01:49:26.026+0000] {logging_mixin.py:190} INFO - [2025-03-15T01:49:26.026+0000] {base.py:84} INFO - Retrieving connection 'snowflake_conn'
[2025-03-15T01:49:26.026+0000] {logging_mixin.py:190} INFO - [2025-03-15T01:49:26.026+0000] {connection.py:413} INFO - Snowflake Connector for Python Version: 3.12.1, Python Version: 3.12.5, Platform: Linux-6.12.5-linuxkit-aarch64-with-glibc2.36
[2025-03-15T01:49:26.030+0000] {logging_mixin.py:190} INFO - [2025-03-15T01:49:26.030+0000] {connection.py:1196} INFO - Connecting to GLOBAL Snowflake domain
[2025-03-15T01:49:26.030+0000] {logging_mixin.py:190} INFO - [2025-03-15T01:49:26.030+0000] {connection.py:1277} INFO - This connection is in OCSP Fail Open Mode. TLS Certificates would be checked for validity and revocation status. Any other Certificate Revocation related exceptions or OCSP Responder failures would be disregarded in favor of connectivity.
[2025-03-15T01:49:26.308+0000] {logging_mixin.py:190} INFO - [2025-03-15T01:49:26.306+0000] {dagbag.py:386} ERROR - Failed to import: /opt/airflow/dags/train_predict.py
Traceback (most recent call last):
  File "/home/airflow/.local/lib/python3.12/site-packages/airflow/models/dagbag.py", line 382, in parse
    loader.exec_module(new_module)
  File "<frozen importlib._bootstrap_external>", line 995, in exec_module
  File "<frozen importlib._bootstrap>", line 488, in _call_with_frames_removed
  File "/opt/airflow/dags/train_predict.py", line 96, in <module>
    cur = return_snowflake_conn()
          ^^^^^^^^^^^^^^^^^^^^^^^
  File "/opt/airflow/dags/train_predict.py", line 18, in return_snowflake_conn
    conn = hook.get_conn()
           ^^^^^^^^^^^^^^^
  File "/home/airflow/.local/lib/python3.12/site-packages/airflow/providers/snowflake/hooks/snowflake.py", line 300, in get_conn
    conn = connector.connect(**conn_config)
           ^^^^^^^^^^^^^^^^^^^^^^^^^^^^^^^^
  File "/home/airflow/.local/lib/python3.12/site-packages/snowflake/connector/__init__.py", line 55, in Connect
    return SnowflakeConnection(**kwargs)
           ^^^^^^^^^^^^^^^^^^^^^^^^^^^^^
  File "/home/airflow/.local/lib/python3.12/site-packages/snowflake/connector/connection.py", line 456, in __init__
    self.connect(**kwargs)
  File "/home/airflow/.local/lib/python3.12/site-packages/snowflake/connector/connection.py", line 771, in connect
    self.__open_connection()
  File "/home/airflow/.local/lib/python3.12/site-packages/snowflake/connector/connection.py", line 1099, in __open_connection
    self.authenticate_with_retry(self.auth_class)
  File "/home/airflow/.local/lib/python3.12/site-packages/snowflake/connector/connection.py", line 1386, in authenticate_with_retry
    self._authenticate(auth_instance)
  File "/home/airflow/.local/lib/python3.12/site-packages/snowflake/connector/connection.py", line 1414, in _authenticate
    auth.authenticate(
  File "/home/airflow/.local/lib/python3.12/site-packages/snowflake/connector/auth/_auth.py", line 401, in authenticate
    Error.errorhandler_wrapper(
  File "/home/airflow/.local/lib/python3.12/site-packages/snowflake/connector/errors.py", line 284, in errorhandler_wrapper
    handed_over = Error.hand_to_other_handler(
                  ^^^^^^^^^^^^^^^^^^^^^^^^^^^^
  File "/home/airflow/.local/lib/python3.12/site-packages/snowflake/connector/errors.py", line 342, in hand_to_other_handler
    connection.errorhandler(connection, cursor, error_class, error_value)
  File "/home/airflow/.local/lib/python3.12/site-packages/snowflake/connector/errors.py", line 215, in default_errorhandler
    raise error_class(
snowflake.connector.errors.DatabaseError: 250001 (08001): None: Failed to connect to DB: EYRGUED-VJB46211.snowflakecomputing.com:443. Your user account has been temporarily locked. Try again later or contact your account administrator for assistance. For more information about this error, go to https://community.snowflake.com/s/error-your-user-login-has-been-locked.
[2025-03-15T01:49:26.309+0000] {processor.py:927} WARNING - No viable dags retrieved from /opt/airflow/dags/train_predict.py
[2025-03-15T01:49:26.317+0000] {processor.py:208} INFO - Processing /opt/airflow/dags/train_predict.py took 0.331 seconds
[2025-03-15T02:36:31.410+0000] {processor.py:186} INFO - Started process (PID=425) to work on /opt/airflow/dags/train_predict.py
[2025-03-15T02:36:31.411+0000] {processor.py:914} INFO - Processing file /opt/airflow/dags/train_predict.py for tasks to queue
[2025-03-15T02:36:31.413+0000] {logging_mixin.py:190} INFO - [2025-03-15T02:36:31.412+0000] {dagbag.py:587} INFO - Filling up the DagBag from /opt/airflow/dags/train_predict.py
[2025-03-15T02:36:31.421+0000] {logging_mixin.py:190} INFO - [2025-03-15T02:36:31.421+0000] {base.py:84} INFO - Retrieving connection 'snowflake_conn'
[2025-03-15T02:36:31.422+0000] {logging_mixin.py:190} INFO - [2025-03-15T02:36:31.422+0000] {connection.py:413} INFO - Snowflake Connector for Python Version: 3.12.1, Python Version: 3.12.5, Platform: Linux-6.12.5-linuxkit-aarch64-with-glibc2.36
[2025-03-15T02:36:31.423+0000] {logging_mixin.py:190} INFO - [2025-03-15T02:36:31.423+0000] {connection.py:1196} INFO - Connecting to GLOBAL Snowflake domain
[2025-03-15T02:36:31.424+0000] {logging_mixin.py:190} INFO - [2025-03-15T02:36:31.424+0000] {connection.py:1277} INFO - This connection is in OCSP Fail Open Mode. TLS Certificates would be checked for validity and revocation status. Any other Certificate Revocation related exceptions or OCSP Responder failures would be disregarded in favor of connectivity.
[2025-03-15T02:36:31.746+0000] {logging_mixin.py:190} INFO - [2025-03-15T02:36:31.745+0000] {dagbag.py:386} ERROR - Failed to import: /opt/airflow/dags/train_predict.py
Traceback (most recent call last):
  File "/home/airflow/.local/lib/python3.12/site-packages/airflow/models/dagbag.py", line 382, in parse
    loader.exec_module(new_module)
  File "<frozen importlib._bootstrap_external>", line 995, in exec_module
  File "<frozen importlib._bootstrap>", line 488, in _call_with_frames_removed
  File "/opt/airflow/dags/train_predict.py", line 96, in <module>
    cur = return_snowflake_conn()
          ^^^^^^^^^^^^^^^^^^^^^^^
  File "/opt/airflow/dags/train_predict.py", line 18, in return_snowflake_conn
    conn = hook.get_conn()
           ^^^^^^^^^^^^^^^
  File "/home/airflow/.local/lib/python3.12/site-packages/airflow/providers/snowflake/hooks/snowflake.py", line 300, in get_conn
    conn = connector.connect(**conn_config)
           ^^^^^^^^^^^^^^^^^^^^^^^^^^^^^^^^
  File "/home/airflow/.local/lib/python3.12/site-packages/snowflake/connector/__init__.py", line 55, in Connect
    return SnowflakeConnection(**kwargs)
           ^^^^^^^^^^^^^^^^^^^^^^^^^^^^^
  File "/home/airflow/.local/lib/python3.12/site-packages/snowflake/connector/connection.py", line 456, in __init__
    self.connect(**kwargs)
  File "/home/airflow/.local/lib/python3.12/site-packages/snowflake/connector/connection.py", line 771, in connect
    self.__open_connection()
  File "/home/airflow/.local/lib/python3.12/site-packages/snowflake/connector/connection.py", line 1099, in __open_connection
    self.authenticate_with_retry(self.auth_class)
  File "/home/airflow/.local/lib/python3.12/site-packages/snowflake/connector/connection.py", line 1386, in authenticate_with_retry
    self._authenticate(auth_instance)
  File "/home/airflow/.local/lib/python3.12/site-packages/snowflake/connector/connection.py", line 1414, in _authenticate
    auth.authenticate(
  File "/home/airflow/.local/lib/python3.12/site-packages/snowflake/connector/auth/_auth.py", line 401, in authenticate
    Error.errorhandler_wrapper(
  File "/home/airflow/.local/lib/python3.12/site-packages/snowflake/connector/errors.py", line 284, in errorhandler_wrapper
    handed_over = Error.hand_to_other_handler(
                  ^^^^^^^^^^^^^^^^^^^^^^^^^^^^
  File "/home/airflow/.local/lib/python3.12/site-packages/snowflake/connector/errors.py", line 342, in hand_to_other_handler
    connection.errorhandler(connection, cursor, error_class, error_value)
  File "/home/airflow/.local/lib/python3.12/site-packages/snowflake/connector/errors.py", line 215, in default_errorhandler
    raise error_class(
snowflake.connector.errors.DatabaseError: 250001 (08001): None: Failed to connect to DB: EYRGUED-VJB46211.snowflakecomputing.com:443. Your user account has been temporarily locked. Try again later or contact your account administrator for assistance. For more information about this error, go to https://community.snowflake.com/s/error-your-user-login-has-been-locked.
[2025-03-15T02:36:31.747+0000] {processor.py:927} WARNING - No viable dags retrieved from /opt/airflow/dags/train_predict.py
[2025-03-15T02:36:31.754+0000] {processor.py:208} INFO - Processing /opt/airflow/dags/train_predict.py took 0.348 seconds
[2025-03-15T02:49:55.187+0000] {processor.py:186} INFO - Started process (PID=467) to work on /opt/airflow/dags/train_predict.py
[2025-03-15T02:49:55.188+0000] {processor.py:914} INFO - Processing file /opt/airflow/dags/train_predict.py for tasks to queue
[2025-03-15T02:49:55.189+0000] {logging_mixin.py:190} INFO - [2025-03-15T02:49:55.189+0000] {dagbag.py:587} INFO - Filling up the DagBag from /opt/airflow/dags/train_predict.py
[2025-03-15T02:49:55.204+0000] {logging_mixin.py:190} INFO - [2025-03-15T02:49:55.204+0000] {base.py:84} INFO - Retrieving connection 'snowflake_conn'
[2025-03-15T02:49:55.205+0000] {logging_mixin.py:190} INFO - [2025-03-15T02:49:55.205+0000] {connection.py:413} INFO - Snowflake Connector for Python Version: 3.12.1, Python Version: 3.12.5, Platform: Linux-6.12.5-linuxkit-aarch64-with-glibc2.36
[2025-03-15T02:49:55.206+0000] {logging_mixin.py:190} INFO - [2025-03-15T02:49:55.206+0000] {connection.py:1196} INFO - Connecting to GLOBAL Snowflake domain
[2025-03-15T02:49:55.206+0000] {logging_mixin.py:190} INFO - [2025-03-15T02:49:55.206+0000] {connection.py:1277} INFO - This connection is in OCSP Fail Open Mode. TLS Certificates would be checked for validity and revocation status. Any other Certificate Revocation related exceptions or OCSP Responder failures would be disregarded in favor of connectivity.
[2025-03-15T02:49:55.491+0000] {logging_mixin.py:190} INFO - [2025-03-15T02:49:55.490+0000] {dagbag.py:386} ERROR - Failed to import: /opt/airflow/dags/train_predict.py
Traceback (most recent call last):
  File "/home/airflow/.local/lib/python3.12/site-packages/airflow/models/dagbag.py", line 382, in parse
    loader.exec_module(new_module)
  File "<frozen importlib._bootstrap_external>", line 995, in exec_module
  File "<frozen importlib._bootstrap>", line 488, in _call_with_frames_removed
  File "/opt/airflow/dags/train_predict.py", line 96, in <module>
    cur = return_snowflake_conn()
          ^^^^^^^^^^^^^^^^^^^^^^^
  File "/opt/airflow/dags/train_predict.py", line 18, in return_snowflake_conn
    conn = hook.get_conn()
           ^^^^^^^^^^^^^^^
  File "/home/airflow/.local/lib/python3.12/site-packages/airflow/providers/snowflake/hooks/snowflake.py", line 300, in get_conn
    conn = connector.connect(**conn_config)
           ^^^^^^^^^^^^^^^^^^^^^^^^^^^^^^^^
  File "/home/airflow/.local/lib/python3.12/site-packages/snowflake/connector/__init__.py", line 55, in Connect
    return SnowflakeConnection(**kwargs)
           ^^^^^^^^^^^^^^^^^^^^^^^^^^^^^
  File "/home/airflow/.local/lib/python3.12/site-packages/snowflake/connector/connection.py", line 456, in __init__
    self.connect(**kwargs)
  File "/home/airflow/.local/lib/python3.12/site-packages/snowflake/connector/connection.py", line 771, in connect
    self.__open_connection()
  File "/home/airflow/.local/lib/python3.12/site-packages/snowflake/connector/connection.py", line 1099, in __open_connection
    self.authenticate_with_retry(self.auth_class)
  File "/home/airflow/.local/lib/python3.12/site-packages/snowflake/connector/connection.py", line 1386, in authenticate_with_retry
    self._authenticate(auth_instance)
  File "/home/airflow/.local/lib/python3.12/site-packages/snowflake/connector/connection.py", line 1414, in _authenticate
    auth.authenticate(
  File "/home/airflow/.local/lib/python3.12/site-packages/snowflake/connector/auth/_auth.py", line 401, in authenticate
    Error.errorhandler_wrapper(
  File "/home/airflow/.local/lib/python3.12/site-packages/snowflake/connector/errors.py", line 284, in errorhandler_wrapper
    handed_over = Error.hand_to_other_handler(
                  ^^^^^^^^^^^^^^^^^^^^^^^^^^^^
  File "/home/airflow/.local/lib/python3.12/site-packages/snowflake/connector/errors.py", line 342, in hand_to_other_handler
    connection.errorhandler(connection, cursor, error_class, error_value)
  File "/home/airflow/.local/lib/python3.12/site-packages/snowflake/connector/errors.py", line 215, in default_errorhandler
    raise error_class(
snowflake.connector.errors.DatabaseError: 250001 (08001): None: Failed to connect to DB: EYRGUED-VJB46211.snowflakecomputing.com:443. Your user account has been temporarily locked. Try again later or contact your account administrator for assistance. For more information about this error, go to https://community.snowflake.com/s/error-your-user-login-has-been-locked.
[2025-03-15T02:49:55.492+0000] {processor.py:927} WARNING - No viable dags retrieved from /opt/airflow/dags/train_predict.py
[2025-03-15T02:49:55.497+0000] {processor.py:208} INFO - Processing /opt/airflow/dags/train_predict.py took 0.313 seconds
[2025-03-15T02:50:25.847+0000] {processor.py:186} INFO - Started process (PID=505) to work on /opt/airflow/dags/train_predict.py
[2025-03-15T02:50:25.849+0000] {processor.py:914} INFO - Processing file /opt/airflow/dags/train_predict.py for tasks to queue
[2025-03-15T02:50:25.849+0000] {logging_mixin.py:190} INFO - [2025-03-15T02:50:25.849+0000] {dagbag.py:587} INFO - Filling up the DagBag from /opt/airflow/dags/train_predict.py
[2025-03-15T02:50:25.864+0000] {logging_mixin.py:190} INFO - [2025-03-15T02:50:25.864+0000] {base.py:84} INFO - Retrieving connection 'snowflake_conn'
[2025-03-15T02:50:25.865+0000] {logging_mixin.py:190} INFO - [2025-03-15T02:50:25.865+0000] {connection.py:413} INFO - Snowflake Connector for Python Version: 3.12.1, Python Version: 3.12.5, Platform: Linux-6.12.5-linuxkit-aarch64-with-glibc2.36
[2025-03-15T02:50:25.866+0000] {logging_mixin.py:190} INFO - [2025-03-15T02:50:25.866+0000] {connection.py:1196} INFO - Connecting to GLOBAL Snowflake domain
[2025-03-15T02:50:25.869+0000] {logging_mixin.py:190} INFO - [2025-03-15T02:50:25.869+0000] {connection.py:1277} INFO - This connection is in OCSP Fail Open Mode. TLS Certificates would be checked for validity and revocation status. Any other Certificate Revocation related exceptions or OCSP Responder failures would be disregarded in favor of connectivity.
[2025-03-15T02:50:26.097+0000] {logging_mixin.py:190} INFO - [2025-03-15T02:50:26.095+0000] {dagbag.py:386} ERROR - Failed to import: /opt/airflow/dags/train_predict.py
Traceback (most recent call last):
  File "/home/airflow/.local/lib/python3.12/site-packages/airflow/models/dagbag.py", line 382, in parse
    loader.exec_module(new_module)
  File "<frozen importlib._bootstrap_external>", line 995, in exec_module
  File "<frozen importlib._bootstrap>", line 488, in _call_with_frames_removed
  File "/opt/airflow/dags/train_predict.py", line 96, in <module>
    cur = return_snowflake_conn()
          ^^^^^^^^^^^^^^^^^^^^^^^
  File "/opt/airflow/dags/train_predict.py", line 18, in return_snowflake_conn
    conn = hook.get_conn()
           ^^^^^^^^^^^^^^^
  File "/home/airflow/.local/lib/python3.12/site-packages/airflow/providers/snowflake/hooks/snowflake.py", line 300, in get_conn
    conn = connector.connect(**conn_config)
           ^^^^^^^^^^^^^^^^^^^^^^^^^^^^^^^^
  File "/home/airflow/.local/lib/python3.12/site-packages/snowflake/connector/__init__.py", line 55, in Connect
    return SnowflakeConnection(**kwargs)
           ^^^^^^^^^^^^^^^^^^^^^^^^^^^^^
  File "/home/airflow/.local/lib/python3.12/site-packages/snowflake/connector/connection.py", line 456, in __init__
    self.connect(**kwargs)
  File "/home/airflow/.local/lib/python3.12/site-packages/snowflake/connector/connection.py", line 771, in connect
    self.__open_connection()
  File "/home/airflow/.local/lib/python3.12/site-packages/snowflake/connector/connection.py", line 1099, in __open_connection
    self.authenticate_with_retry(self.auth_class)
  File "/home/airflow/.local/lib/python3.12/site-packages/snowflake/connector/connection.py", line 1386, in authenticate_with_retry
    self._authenticate(auth_instance)
  File "/home/airflow/.local/lib/python3.12/site-packages/snowflake/connector/connection.py", line 1414, in _authenticate
    auth.authenticate(
  File "/home/airflow/.local/lib/python3.12/site-packages/snowflake/connector/auth/_auth.py", line 401, in authenticate
    Error.errorhandler_wrapper(
  File "/home/airflow/.local/lib/python3.12/site-packages/snowflake/connector/errors.py", line 284, in errorhandler_wrapper
    handed_over = Error.hand_to_other_handler(
                  ^^^^^^^^^^^^^^^^^^^^^^^^^^^^
  File "/home/airflow/.local/lib/python3.12/site-packages/snowflake/connector/errors.py", line 342, in hand_to_other_handler
    connection.errorhandler(connection, cursor, error_class, error_value)
  File "/home/airflow/.local/lib/python3.12/site-packages/snowflake/connector/errors.py", line 215, in default_errorhandler
    raise error_class(
snowflake.connector.errors.DatabaseError: 250001 (08001): None: Failed to connect to DB: EYRGUED-VJB46211.snowflakecomputing.com:443. Your user account has been temporarily locked. Try again later or contact your account administrator for assistance. For more information about this error, go to https://community.snowflake.com/s/error-your-user-login-has-been-locked.
[2025-03-15T02:50:26.098+0000] {processor.py:927} WARNING - No viable dags retrieved from /opt/airflow/dags/train_predict.py
[2025-03-15T02:50:26.105+0000] {processor.py:208} INFO - Processing /opt/airflow/dags/train_predict.py took 0.262 seconds
